# Try Catch Finally

Try Catch Finally는 에러 처리를 구현하는 방법.

```
try{
    setTimeout(()=> {throw new Error('Error!');, 1000});
}
catch(e){
    //에러를 캐치하지 못한다.
    console.log(e);
}

//
```

Try 코드 블록 실행되고,
Try 코드 블록에 포함된 문 중에서 에러가 발생하면 해당 에러는 catch문의 err 변수에 전달 되고
catch 코드 블록이 실행된다. finally 코드 블록은 에러 발생과 상관없이 반드시 한 번 실행된다.
