# 에러처리

에러처리를 하는 방법은 두 가지가 있다. <br />

1. 예외상황이 발생하면 반환하는 값(-1 이나 null)을 if문 이나 단축 평가를 통해 확인하기

2. 에러처리 코드를 미리 등록해두고 에러가 발생하면 에러처리코드로 점프하도록 만들기 (Try Catch Finally)

<br />

### Try Catch Finally

Try Catch Finally문으로 에러처리를 하면 프로그램이 강제 종료되지 않는다.
Try 코드 블록 실행되고,
Try 코드 블록에 포함된 문 중에서 에러가 발생하면 해당 에러는 catch문의 err 변수에 전달 되고
catch 코드 블록이 실행된다. finally 코드 블록은 에러 발생과 상관없이 반드시 한 번 실행된다.

```
try{
    //실행항 코드(에러가 발생 할 가능성이 있는 코드)
}
catch(e){
    //try 코드 블록에서 에러가 발생하면 이 코드 블록의 코드가 실행된다.

} finally {
    //에러 발생과 상관없이 반드시 한 번 실행된다.
}

//
```

### Error 객체

Error 생성자 함수는 에러 객체를 생성한다.

```
const error = new Error('failed');
```

### throw 문

Error 생성자 함수로 에러 객체를 생성한다고 에러가 발생하는 것은 아니다. **에러 객체 생성**과 **에러 발생**은 의미가 다르다.

```
try{
    // 에러 객체만 생성한 것이지 에러를 발생시킨 것은 아니다.
    new Error('error 객체 생성');
} catch(e){
    console.log(e);
}
```

```
try{
    //에러 객체를 던져야한다.
    throw new Error('error');
} catch(e){
    console.log(e);
}
```

### 에러의 전파

에러는 **호출자 방향**으로 전파된다. 즉, **콜 스택의 아래 방향**으로 전파된다.

```
const a = () => {
    throw new Error('error');
};

const b = () => {
    a();
};

const c = () => {
    b();
};

try{
    c();
} catch (err){
    console.error(err);
}

```

```

|          a   -> Error! |
|          b             |
|          c             |
|          전역           |
 -------------------------
```

### 주의 사항

```

try{
    setTimeout(()=> {throw new Error('Error!');, 1000});
}
catch(e){
    //에러를 캐치하지 못한다.
    console.log(e);
}

//

```

setTimeout 함수는 콜백 함수의 호출이 실행되기전에 종료된다. 따라서 에러를 호출한 인자가 없으므로, 정상적으로 에러가 발생하지 않는다. setTimeout외에도 프로미스의 후속처리 메서드의 콜백함수도 에러를 전파 할 호출자가 없으니 주의해야한다.
